{"content": {"suites": {"0": {"status": {"total_pass": 0, "total_skip": 0, "total_xpass": 0, "total_xfail": 0, "total_rerun": 0, "total_fail": 1, "total_error": 0}, "tests": {"0": {"status": "FAIL", "message": "           ConnectionRefusedError: [WinError 10061] No connection could be made because the target machine actively refused it\n       urllib3.exceptions.NewConnectionError: <urllib3.connection.HTTPConnection object at 0x00000219E1A52DD0>: Failed to establish a new connection: [WinError 10061] No connection could be made because the target machine actively refused it\n       urllib3.exceptions.MaxRetryError: HTTPConnectionPool(host='localhost', port=8835): Max retries exceeded with url: /session/1cc8bf4ff7e81b0601396c5ed2c42118/element (Caused by NewConnectionError('<urllib3.connection.HTTPConnection object at 0x00000219E1A52DD0>: Failed to establish a new connection: [WinError 10061] No connection could be made because the target machine actively refused it'))\n", "test_name": "test_valid_login_with_sql", "rerun": "0"}}, "suite_name": "SQL/test_valid_login_with_sql_infos.py"}}}, "date": "May 05, 2024", "start_time": 1714857733.8858407, "total_suite": 1, "status": "FAIL", "status_list": {"pass": "0", "fail": "1", "skip": "0", "error": "0", "xpass": "0", "xfail": "0", "rerun": "0"}, "total_tests": "1"}